<robot name="metabot">

  <!-- Component two_wheels#1 -->

  <link name="two_wheels_1">
    <visual>
      <geometry>
        <mesh filename="package://94459fd27acfd944bd077d0df1458db2b1ca6c78.stl"/>
      </geometry>
      <material name="two_wheels_two_wheels_1_0_material">
        <color rgba="0.6 0.6 0.8 1.0"/>
      </material>
    <origin xyz="0 0 0" rpy="0 -0 0"/>
    </visual>
  <inertial>
    <origin xyz="-0.0125599 0 0.00336508" rpy="0 0 0"/>
    <mass value="0.0256625"/>
    <inertia ixx="1.00044e-05"  ixy="2.84994e-22"  ixz="6.67932e-07" iyy="9.56137e-06" iyz="2.30926e-23" izz="1.79804e-05" />
  </inertial>
  <collision>
    <origin xyz="-0.0260323 0 0.00687874" rpy="0 -0.122173 0"/>
    <geometry>
      <box size="0.0498 0.0098 0.0198"/>
    </geometry>
  </collision>
  <collision>
    <origin xyz="0 0 0" rpy="0 -0.122173 0"/>
    <geometry>
      <box size="0.0398 0.0898 0.0028"/>
    </geometry>
  </collision>
  </link>
<link name="two_wheels_1_tip">
    <inertial>
    <origin xyz="0 0 0" rpy="0 0 0" />
    <mass value="0" />
    <inertia ixx="0" ixy="0" ixz="0" iyy="0" iyz="0" izz="0" />
    </inertial>
</link>
<joint name="two_wheels_1_tip" type="fixed">
<origin xyz="0 0 0" rpy="0 -0 0"/>
    <parent link="two_wheels_1" />
    <child link="two_wheels_1_tip" />
    <axis xyz="0 0 0" />
</joint>

  <!-- Component wheel_regular#2 -->

  <link name="wheel_regular_2">
    <visual>
      <geometry>
        <mesh filename="package://1d5055d3df339ba1e4544fb607d061fdc7b37cd1.stl"/>
      </geometry>
      <material name="wheel_regular_wheel_regular_2_0_material">
        <color rgba="0.5 0.5 0.5 1.0"/>
      </material>
    <origin xyz="0 0 0" rpy="1.5708 -0.122173 0"/>
    </visual>
  <inertial>
    <origin xyz="1.35302e-20 0.0005 -1.10195e-19" rpy="0 0 0"/>
    <mass value="0.011325"/>
    <inertia ixx="1.79688e-06"  ixy="0"  ixz="0" iyy="1.79713e-06" iyz="0" izz="3.54871e-06" />
  </inertial>
  <collision>
    <origin xyz="0 0 0" rpy="1.5708 -0.122173 0"/>
    <geometry>
      <cylinder radius="0.0248" length="0.0048"/>
    </geometry>
  </collision>
  </link>
  <joint name="wheel_regular_2" type="revolute">
    <parent link="two_wheels_1"/>
    <child link="wheel_regular_2"/>
    <axis xyz="0 1 0"/>
<origin xyz="0 -0.05 0" rpy="0 5.96384e-33 0"/>
    <limit effort="0.5" velocity="12.5664" />
    <joint_properties friction="0.0"/>
  </joint>

  <!-- Component wheel_regular#3 -->

  <link name="wheel_regular_3">
    <visual>
      <geometry>
        <mesh filename="package://1d5055d3df339ba1e4544fb607d061fdc7b37cd1.stl"/>
      </geometry>
      <material name="wheel_regular_wheel_regular_3_0_material">
        <color rgba="0.5 0.5 0.5 1.0"/>
      </material>
    <origin xyz="0 0 0" rpy="1.5708 -0.122173 0"/>
    </visual>
  <inertial>
    <origin xyz="1.35302e-20 0.0005 -1.10195e-19" rpy="0 0 0"/>
    <mass value="0.011325"/>
    <inertia ixx="1.79688e-06"  ixy="0"  ixz="0" iyy="1.79713e-06" iyz="0" izz="3.54871e-06" />
  </inertial>
  <collision>
    <origin xyz="0 0 0" rpy="1.5708 -0.122173 0"/>
    <geometry>
      <cylinder radius="0.0248" length="0.0048"/>
    </geometry>
  </collision>
  </link>
  <joint name="wheel_regular_3" type="revolute">
    <parent link="two_wheels_1"/>
    <child link="wheel_regular_3"/>
    <axis xyz="0 1 0"/>
<origin xyz="0 0.05 0" rpy="0 5.96384e-33 0"/>
    <limit effort="0.5" velocity="12.5664" />
    <joint_properties friction="0.0"/>
  </joint>
</robot>
